Workbook

Sheet سبتمبر2025
C2: سبتمبر - 2025
C3: الدائرة | D3: رئيس الدائرة | E3: امين سر الجلسة | F3: عدد الطلبات المسجلة | G3: عدد الدعاوى المسجلة | H3: عدد الدعاوى المتداولة | I3: عدد الدعاوى المحكومة | J3: عدد الدعاوى المحالة | K3: نسبة الإنجاز | L3: عدد الدعاوى المرحلة | M3: عدد الدعاوى المحجوزة للحكم | N3: المتبقي للتداول | O3: احكام اليوم الواحد | P3: عدد الجلسات الالكترونية
C4: الدائرة الأولى تركات كلي | D4: د/ناصر عمران الكواري | E4: محمد رشدي | F4: 43 | G4: 16 | H4: 36 | I4: 17 | J4: 1 | K4: 0.56 | L4: 10 | M4: 6 | N4: 16 | O4: 0 | P4: 0
C5: الدائرة الثانية أسرة كلي | D5: محمد طايس الجميلي | E5: يوسف وحيد | F5: 134 | G5: 50 | H5: 138 | I5: 85 | J5: 2 | K5: 0.72 | L5: 30 | M5: 9 | N5: 39 | O5: 10 | P5: 5
C6: الدائرة الثالثةاستئناف | D6: دكتور عايض سعد القحطاني | E6: محمد على | F6: 36 | G6: 22 | H6: 74 | I6: 57 | J6: 1 | K6: 0.78 | L6: 3 | M6: 13 | N6: 16 | O6: 5 | P6: 3
C7: الدائرة الرابعة اسرة كلي | D7: موسي إبراهيم الهتمي | E7: سعيد الهاجري | F7: 105 | G7: 59 | H7: 158 | I7: 103 | J7: 6 | K7: 0.75 | L7: 39 | M7: 0 | N7: 39 | O7: 5 | P7: 0
C8: الدائرة الخامسة أسرة كلي | D8: حارب راشد المهندي | E8: محمد عبد الحليم | F8: 116 | G8: 53 | H8: 162 | I8: 90 | J8: 6 | K8: 0.71 | L8: 41 | M8: 6 | N8: 47 | O8: 9 | P8: 3
C9: الدائرة السادسة استئناف | D9: سعود محمد البوعينين | E9: محمد جمال | F9: 1 | G9: 12 | H9: 17 | I9: 12 | J9: 5 | K9: 1 | L9: 0 | M9: 0 | N9: 0 | O9: 3 | P9: 0
C10: الدائرة السابعة أسرة كلي | D10: محمد عبد الهادي الدوسري | E10: بدر الدين | F10: 70 | G10: 58 | H10: 122 | I10: 90 | J10: 1 | K10: 0.85 | L10: 18 | M10: 0 | N10: 18 | O10: 25 | P10: 4
C11: الدائرة الاولى جزئي | D11: سعد احمد السيلطي | E11: نعمة الله | F11: 63 | G11: 29 | H11: 94 | I11: 63 | J11: 0 | K11: 0.68 | L11: 25 | M11: 5 | N11: 30 | O11: 19 | P11: 0
C12: الدائرة الثانيةجزئي | D12: ماجد محمد العنزي | E12: ناصر العثمان | F12: 42 | G12: 36 | H12: 55 | I12: 36 | J12: 0 | K12: 0.69 | L12: 10 | M12: 7 | N12: 17 | O12: 9 | P12: 1
C13: الدائرة الثالثة جزئي | D13: محمد احمد صالح | E13: خالد العبدالله | F13: 64 | G13: 63 | H13: 80 | I13: 66 | J13: 1 | K13: 0.91 | L13: 7 | M13: 0 | N13: 7 | O13: 63 | P13: 0
C14: الدائرة الرابعة جزئي | D14: راجي جعفر سيد | E14: سارة الهاجري | F14: 90 | G14: 37 | H14: 132 | I14: 106 | J14: 0 | K14: 0.89 | L14: 14 | M14: 0 | N14: 14 | O14: 95 | P14: 0
C15: الدائرة الخامسة قاصرين | D15: ابراهيم غصاب العدوي | E15: غالية الحبشي | F15: 24 | G15: 24 | H15: 69 | I15: 48 | J15: 0 | K15: 0.84 | L15: 9 | M15: 2 | N15: 11 | O15: 8 | P15: 0
... C18: الدائرة التاسعة تركات | D18: على خالد الانصاري | E18: محمود عساف | F18: 134 | G18: 50 | H18: 23 | I18: 5 | J18: 1 | K18: 0.26 | L18: 13 | M18: 4 | N18: 17 | O18: 0 | P18: 2
C19: المجموع | F19: =SUM(F4:F18) -> 1019 | G19: =SUM(G4:G18) -> 564 | H19: =SUM(H4:H18) -> 1304 | I19: =SUM(I4:I18) -> 858 | J19: =SUM(J4:J18) -> 26 | K19: 0.75 | L19: =SUM(L4:L18) -> 253 | M19: =SUM(M4:M18) -> 71 | N19: =SUM(N4:N18) -> 324 | O19: =SUM(O4:O18) -> 270 | P19: =SUM(P4:P18) -> 18

Sheet اكتوبر2025
C2: اكتوبر-2025
C3: الدائرة | D3: رئيس الدائرة | E3: امين سر الجلسة | F3: عدد الطلبات المسجلة | G3: عدد الدعاوى المسجلة | H3: عدد الدعاوى المتداولة | I3: عدد الدعاوى المحكومة | J3: عدد الدعاوى المحالة | K3: نسبة الإنجاز | L3: عدد الدعاوى المرحلة | M3: عدد الدعاوى المحجوزة للحكم | N3: المتبقي للتداول | O3: احكام اليوم الواحد | P3: عدد الجلسات الالكترونية
C4: الدائرة الأولى تركات كلي | D4: د/ناصر عمران الكواري | E4: محمد رشدي | F4: 58 | G4: 12 | H4: 30 | I4: 11 | J4: 0 | K4: 0.37 | L4: 19 | M4: 4 | N4: 15 | O4: 0 | P4: 0
C5: الدائرة الثانية أسرة كلي | D5: محمد طايس الجميلي | E5: يوسف وحيد | F5: 119 | G5: 86 | H5: 117 | I5: 55 | J5: 0 | K5: 0.5 | L5: 58 | M5: 17 | N5: 41 | O5: 16 | P5: 20
C6: الدائرة الثالثةاستئناف | D6: دكتور عايض سعد القحطاني | E6: محمد على | F6: 34 | G6: 53 | H6: 65 | I6: 38 | J6: 2 | K6: 0.62 | L6: 25 | M6: 12 | N6: 13 | O6: 10 | P6: 7
C7: الدائرة الرابعة اسرة كلي | D7: موسي إبراهيم الهتمي | E7: سعيد الهاجري | F7: 79 | G7: 45 | H7: 95 | I7: 61 | J7: 3 | K7: 0.83 | L7: 16 | M7: 0 | N7: 16 | O7: 1 | P7: 5
C8: الدائرة الخامسة أسرة كلي | D8: حارب راشد المهندي | E8: محمد عبد الحليم | F8: 80 | G8: 54 | H8: 98 | I8: 61 | J8: 0 | K8: 0.66 | L8: 33 | M8: 1 | N8: 32 | O8: 2 | P8: 12
C9: الدائرة السادسة استئناف | D9: سعود محمد البوعينين | E9: محمد جمال | F9: 15 | G9: 48 | H9: 35 | I9: 17 | J9: 4 | K9: 0.6 | L9: 14 | M9: 7 | N9: 7 | O9: 0 | P9: 0
C10: الدائرة السابعة أسرة كلي | D10: محمد عبد الهادي الدوسري | E10: بدر الدين | F10: 85 | G10: 75 | H10: 90 | I10: 60 | J10: 2 | K10: 0.81 | L10: 17 | M10: 0 | N10: 17 | O10: 17 | P10: 4
C11: الدائرة الاولى جزئي | D11: سعد احمد السيلطي | E11: نعمة الله | F11: 60 | G11: 40 | H11: 66 | I11: 33 | J11: 0 | K11: 0.5 | L11: 33 | M11: 24 | N11: 9 | O11: 21 | P11: 0
C12: الدائرة الثانيةجزئي | D12: ماجد محمد العنزي | E12: ناصر العثمان | F12: 41 | G12: 38 | H12: 56 | I12: 26 | J12: 2 | K12: 0.59 | L12: 23 | M12: 18 | N12: 5 | O12: 1 | P12: 2
C13: الدائرة الثالثة جزئي | D13: محمد احمد صالح | E13: خالد العبدالله | F13: 50 | G13: 45 | H13: 52 | I13: 43 | J13: 1 | K13: 0.92 | L13: 4 | M13: 0 | N13: 4 | O13: 43 | P13: 6
C14: الدائرة الرابعة جزئي | D14: راجي جعفر سيد | E14: سارة الهاجري | F14: 60 | G14: 44 | H14: 64 | I14: 53 | J14: 0 | K14: 0.88 | L14: 8 | M14: 0 | N14: 8 | O14: 47 | P14: 2
C15: الدائرة الخامسة قاصرين | D15: ابراهيم غصاب العدوي | E15: غالية الحبشي | F15: 22 | G15: 41 | H15: 48 | I15: 34 | J15: 0 | K15: 0.73 | L15: 13 | M15: 0 | N15: 13 | O15: 13 | P15: 0
... C18: الدائرة التاسعة تركات | D18: على خالد الانصاري | E18: محمود عساف | F18: 15 | G18: 6 | H18: 22 | I18: 4 | J18: 0 | K18: 0.23 | L18: 17 | M18: 5 | N18: 12 | O18: 0 | P18: 1
C19: المجموع | F19: =SUM(F4:F18) -> 785 | G19: =SUM(G4:G18) -> 662 | H19: =SUM(H4:H18) -> 961 | I19: =SUM(I4:I18) -> 582 | J19: =SUM(J4:J18) -> 17 | K19: 0.68 | L19: =SUM(L4:L18) -> 306 | M19: =SUM(M4:M18) -> 97 | N19: =SUM(N4:N18) -> 209 | O19: =SUM(O4:O18) -> 210 | P19: =SUM(P4:P18) -> 68

Sheet نوفمبر-2025
C2: نوفمبر -2025
C3: الدائرة | D3: رئيس الدائرة | E3: امين سر الجلسة | F3: عدد الطلبات المسجلة | G3: عدد الدعاوى المسجلة | H3: عدد الدعاوى المتداولة | I3: عدد الدعاوى المحكومة | J3: عدد الدعاوى المحالة | K3: نسبة الإنجاز | L3: عدد الدعاوى المرحلة | M3: عدد الدعاوى المحجوزة للحكم | N3: المتبقي للتداول | O3: احكام اليوم الواحد | P3: عدد الجلسات الالكترونية
C4: الدائرة الأولى تركات كلي | D4: د/ناصر عمران الكواري | E4: محمد رشدي | F4: 39 | G4: 8 | H4: 30 | I4: 16 | J4: 0 | K4: 0.53333333 | L4: 14 | M4: 0 | N4: 14 | O4: 0 | P4: ________
C5: الدائرة الثانية أسرة كلي | D5: محمد طايس الجميلي | E5: يوسف وحيد | F5: 86 | G5: 57 | H5: 138 | I5: 89 | J5: 1 | K5: 0.73913043 | L5: 36 | M5: 6 | N5: 30 | O5: 22 | P5: 27
C6: الدائرة الثالثةاستئناف | D6: دكتور عايض سعد القحطاني | E6: محمد على | F6: 37 | G6: 40 | H6: 74 | I6: 65 | J6: 1 | K6: 0.89189189 | L6: 8 | M6: 5 | N6: 3 | O6: 11 | P6: 6
C7: الدائرة الرابعة اسرة كلي | D7: موسي إبراهيم الهتمي | E7: سعيد الهاجري | F7: 48 | G7: 32 | H7: 61 | I7: 42 | J7: 2 | K7: 0.83606557 | L7: 10 | M7: 0 | N7: 10 | O7: 3 | P7: 2
C8: الدائرة الخامسة أسرة كلي | D8: حارب راشد المهندي | E8: محمد عبد الحليم | F8: 87 | G8: 35 | H8: 82 | I8: 54 | J8: 1 | K8: 0.73170732 | L8: 22 | M8: 2 | N8: 20 | O8: 3 | P8: 5
C9: الدائرة السادسة استئناف | D9: سعود محمد البوعينين | E9: محمد جمال | F9: 24 | G9: 34 | H9: 61 | I9: 47 | J9: 4 | K9: 0.85245902 | L9: 9 | M9: 1 | N9: 8 | O9: 0 | P9: 0
C10: الدائرة السابعة أسرة كلي | D10: محمد عبد الهادي الدوسري | E10: بدر الدين | F10: 85 | G10: 49 | H10: 82 | I10: 62 | J10: 3 | K10: 0.84146341 | L10: 13 | M10: 0 | N10: 13 | O10: 11 | P10: 11
C11: الدائرة الاولى جزئي | D11: سعد احمد السيلطي | E11: نعمة الله | F11: 38 | G11: 30 | H11: 72 | I11: 43 | J11: 1 | K11: 0.65277778 | L11: 25 | M11: 13 | N11: 12 | O11: 4 | P11: 0
C12: الدائرة الثانيةجزئي | D12: ماجد محمد العنزي | E12: ناصر العثمان | F12: 23 | G12: 28 | H12: 55 | I12: 35 | J12: 1 | K12: 0.72727273 | L12: 15 | M12: 14 | N12: 1 | O12: 2 | P12: 9
C13: الدائرة الثالثة جزئي | D13: محمد احمد صالح | E13: خالد العبدالله | F13: 48 | G13: 29 | H13: 37 | I13: 31 | J13: 0 | K13: 0.94594595 | L13: 2 | M13: 0 | N13: 2 | O13: 30 | P13: 2
C14: الدائرة الرابعة جزئي | D14: راجي جعفر سيد | E14: سارة الهاجري | F14: 35 | G14: 28 | H14: 45 | I14: 41 | J14: 0 | K14: 0.93333333 | L14: 3 | M14: 0 | N14: 3 | O14: 34 | P14: 7
C15: الدائرة الخامسة قاصرين | D15: ابراهيم غصاب العدوي | E15: غالية الحبشي | F15: 23 | G15: 35 | H15: 41 | I15: 31 | J15: 0 | K15: 0.80487805 | L15: 8 | M15: 0 | N15: 8 | O15: 11 | P15: ________
C16: الدائرة السادسة جزئي | D16: راشد عبدالله النعيمي | E16: حامد عيد | F16: 41 | G16: 30 | H16: 63 | I16: 22 | J16: 2 | K16: 0.44444444 | L16: 35 | M16: 17 | N16: 18 | O16: 0 | P16: 7
C17: الدائرة الثامنة جزئي | D17: خالد عبدالله لبده | E17: محمد فال | F17: 26 | G17: 28 | H17: 43 | I17: 31 | J17: 0 | K17: 0.76744186 | L17: 10 | M17: 2 | N17: 8 | O17: 16 | P17: 2
C18: الدائرة التاسعة تركات | D18: على خالد الانصاري | E18: محمود عساف | F18: 21 | G18: 4 | H18: 23 | I18: 12 | J18: 0 | K18: 0.56521739 | L18: 10 | M18: 1 | N18: 9 | O18: 1 | P18: ________
C19: المجموع | F19: =SUM(F4:F18) -> 661 | G19: =SUM(G4:G18) -> 467 | H19: =SUM(H4:H18) -> 907 | I19: =SUM(I4:I18) -> 621 | J19: =SUM(J4:J18) -> 16 | K19: 0.75744212 | L19: =SUM(L4:L18) -> 220 | M19: =SUM(M4:M18) -> 61 | N19: =SUM(N4:N18) -> 159 | O19: =SUM(O4:O18) -> 148 | P19: =SUM(P4:P18) -> 78

Sheet ديسمبر 2025
C2: ديسمبر -2025
C3: الدائرة | D3: رئيس الدائرة | E3: امين سر الجلسة | F3: عدد الطلبات المسجلة | G3: عدد الدعاوى المسجلة | H3: عدد الدعاوى المتداولة | I3: عدد الدعاوى المحكومة | J3: عدد الدعاوى المحالة | K3: نسبة الإنجاز | L3: عدد الدعاوى المرحلة | M3: عدد الدعاوى المحجوزة للحكم | N3: المتبقي للتداول | O3: احكام اليوم الواحد | P3: عدد الجلسات الالكترونية
C4: الدائرة الأولى تركات كلي | D4: د/ناصر عمران الكواري | E4: محمد رشدي | F4: 17 | G4: 15 | H4: 25 | I4: 11 | J4: 0 | K4: =(الجدول445223479[[#This Row],[عدد الدعاوى المتداولة]]-الجدول445223479[[#This Row],[عدد الدعاوى المرحلة]])/الجدول445223479[[#This Row],[عدد الدعاوى المتداولة]] -> 0.44 | L4: =SUM(الجدول445223479[[#This Row],[عدد الدعاوى المحجوزة للحكم ]:[المتبقي للتداول]]) -> 14 | M4: 2 | N4: 12 | O4: 0 | P4: 0
C5: الدائرة الثانية أسرة كلي | D5: محمد طايس الجميلي | E5: يوسف وحيد | F5: 48 | G5: 54 | H5: 88 | I5: 58 | J5: 0 | K5: =(الجدول445223479[[#This Row],[عدد الدعاوى المتداولة]]-الجدول445223479[[#This Row],[عدد الدعاوى المرحلة]])/الجدول445223479[[#This Row],[عدد الدعاوى المتداولة]] -> 0.75 | L5: =SUM(الجدول445223479[[#This Row],[عدد الدعاوى المحجوزة للحكم ]:[المتبقي للتداول]]) -> 22 | M5: 6 | N5: 16 | O5: 19 | P5: 8
C6: الدائرة الثالثةاستئناف | D6: دكتور عايض سعد القحطاني | E6: محمد على | F6: 6 | G6: 34 | H6: 54 | I6: 51 | J6: 1 | K6: =(الجدول445223479[[#This Row],[عدد الدعاوى المتداولة]]-الجدول445223479[[#This Row],[عدد الدعاوى المرحلة]])/الجدول445223479[[#This Row],[عدد الدعاوى المتداولة]] -> 0.96296296 | L6: =SUM(الجدول445223479[[#This Row],[عدد الدعاوى المحجوزة للحكم ]:[المتبقي للتداول]]) -> 2 | M6: 0 | N6: 2 | O6: 17 | P6: 5
C7: الدائرة الرابعة اسرة كلي | D7: موسي إبراهيم الهتمي | E7: سعيد الهاجري | F7: 26 | G7: 60 | H7: 66 | I7: 30 | J7: 1 | K7: =(الجدول445223479[[#This Row],[عدد الدعاوى المتداولة]]-الجدول445223479[[#This Row],[عدد الدعاوى المرحلة]])/الجدول445223479[[#This Row],[عدد الدعاوى المتداولة]] -> 0.62121212 | L7: =SUM(الجدول445223479[[#This Row],[عدد الدعاوى المحجوزة للحكم ]:[المتبقي للتداول]]) -> 25 | M7: 3 | N7: 22 | O7: 2 | P7: 8
C8: الدائرة الخامسة أسرة كلي | D8: حارب راشد المهندي | E8: محمد عبد الحليم | F8: 61 | G8: 54 | H8: 74 | I8: 45 | J8: 1 | K8: =(الجدول445223479[[#This Row],[عدد الدعاوى المتداولة]]-الجدول445223479[[#This Row],[عدد الدعاوى المرحلة]])/الجدول445223479[[#This Row],[عدد الدعاوى المتداولة]] -> 0.71621622 | L8: =SUM(الجدول445223479[[#This Row],[عدد الدعاوى المحجوزة للحكم ]:[المتبقي للتداول]]) -> 21 | M8: 1 | N8: 20 | O8: 7 | P8: 4
C9: الدائرة السادسة استئناف | D9: سعود محمد البوعينين | E9: محمد جمال | F9: 10 | G9: 33 | H9: 46 | I9: 33 | J9: 0 | K9: =(الجدول445223479[[#This Row],[عدد الدعاوى المتداولة]]-الجدول445223479[[#This Row],[عدد الدعاوى المرحلة]])/الجدول445223479[[#This Row],[عدد الدعاوى المتداولة]] -> 0.7173913 | L9: =SUM(الجدول445223479[[#This Row],[عدد الدعاوى المحجوزة للحكم ]:[المتبقي للتداول]]) -> 13 | M9: 7 | N9: 6 | O9: 0 | P9: 0
C10: الدائرة السابعة أسرة كلي | D10: محمد عبد الهادي الدوسري | E10: بدر الدين | F10: 47 | G10: 103 | H10: 109 | I10: 69 | J10: 0 | K10: =(الجدول445223479[[#This Row],[عدد الدعاوى المتداولة]]-الجدول445223479[[#This Row],[عدد الدعاوى المرحلة]])/الجدول445223479[[#This Row],[عدد الدعاوى المتداولة]] -> 0.71559633 | L10: =SUM(الجدول445223479[[#This Row],[عدد الدعاوى المحجوزة للحكم ]:[المتبقي للتداول]]) -> 31 | M10: 0 | N10: 31 | O10: 17 | P10: 19
C11: الدائرة الاولى جزئي | D11: سعد احمد السيلطي | E11: نعمة الله | F11: 14 | G11: 42 | H11: 64 | I11: 34 | J11: 0 | K11: =(الجدول445223479[[#This Row],[عدد الدعاوى المتداولة]]-الجدول445223479[[#This Row],[عدد الدعاوى المرحلة]])/الجدول445223479[[#This Row],[عدد الدعاوى المتداولة]] -> 0.578125 | L11: =SUM(الجدول445223479[[#This Row],[عدد الدعاوى المحجوزة للحكم ]:[المتبقي للتداول]]) -> 27 | M11: 12 | N11: 15 | O11: 7 | P11: 0
C12: الدائرة الثانيةجزئي | D12: ماجد محمد العنزي | E12: ناصر العثمان | F12: 59 | G12: 41 | H12: 52 | I12: 28 | J12: 1 | K12: =(الجدول445223479[[#This Row],[عدد الدعاوى المتداولة]]-الجدول445223479[[#This Row],[عدد الدعاوى المرحلة]])/الجدول445223479[[#This Row],[عدد الدعاوى المتداولة]] -> 0.59615385 | L12: =SUM(الجدول445223479[[#This Row],[عدد الدعاوى المحجوزة للحكم ]:[المتبقي للتداول]]) -> 21 | M12: 8 | N12: 13 | O12: 2 | P12: 0
C13: الدائرة الثالثة جزئي | D13: محمد احمد صالح | E13: خالد العبدالله | F13: 43 | G13: 59 | H13: 53 | I13: 49 | J13: 0 | K13: =(الجدول445223479[[#This Row],[عدد الدعاوى المتداولة]]-الجدول445223479[[#This Row],[عدد الدعاوى المرحلة]])/الجدول445223479[[#This Row],[عدد الدعاوى المتداولة]] -> 0.94339623 | L13: =SUM(الجدول445223479[[#This Row],[عدد الدعاوى المحجوزة للحكم ]:[المتبقي للتداول]]) -> 3 | M13: 0 | N13: 3 | O13: 48 | P13: 0
C14: الدائرة الرابعة جزئي | D14: راجي جعفر سيد | E14: سارة الهاجري | F14: 35 | G14: 57 | H14: 46 | I14: 42 | J14: 0 | K14: =(الجدول445223479[[#This Row],[عدد الدعاوى المتداولة]]-الجدول445223479[[#This Row],[عدد الدعاوى المرحلة]])/الجدول445223479[[#This Row],[عدد الدعاوى المتداولة]] -> 0.97826087 | L14: =SUM(الجدول445223479[[#This Row],[عدد الدعاوى المحجوزة للحكم ]:[المتبقي للتداول]]) -> 1 | M14: 0 | N14: 1 | O14: 42 | P14: 6
C15: الدائرة الخامسة قاصرين | D15: ابراهيم غصاب العدوي | E15: غالية الحبشي | F15: 13 | G15: 28 | H15: 46 | I15: 30 | J15: 0 | K15: =(الجدول445223479[[#This Row],[عدد الدعاوى المتداولة]]-الجدول445223479[[#This Row],[عدد الدعاوى المرحلة]])/الجدول445223479[[#This Row],[عدد الدعاوى المتداولة]] -> 0.82608696 | L15: =SUM(الجدول445223479[[#This Row],[عدد الدعاوى المحجوزة للحكم ]:[المتبقي للتداول]]) -> 8 | M15: 1 | N15: 7 | O15: 13 | P15: 0
... C18: الدائرة التاسعة تركات | D18: على خالد الانصاري | E18: محمود عساف | F18: 3 | G18: 6 | H18: 17 | I18: 6 | J18: 0 | K18: =(الجدول445223479[[#This Row],[عدد الدعاوى المتداولة]]-الجدول445223479[[#This Row],[عدد الدعاوى المرحلة]])/الجدول445223479[[#This Row],[عدد الدعاوى المتداولة]] -> 0.35294118 | L18: =SUM(الجدول445223479[[#This Row],[عدد الدعاوى المحجوزة للحكم ]:[المتبقي للتداول]]) -> 11 | M18: 1 | N18: 10 | O18: 0 | P18: 0
C19: المجموع | F19: =SUM(F4:F18) -> 407 | G19: =SUM(G4:G18) -> 668 | H19: =SUM(H4:H18) -> 867 | I19: =SUM(I4:I18) -> 566 | J19: =SUM(J4:J18) -> 5 | K19: =(الجدول445223479[[#This Row],[عدد الدعاوى المتداولة]]-الجدول445223479[[#This Row],[عدد الدعاوى المرحلة]])/الجدول445223479[[#This Row],[عدد الدعاوى المتداولة]] -> 0.72202999 | L19: =SUM(L4:L18) -> 241 | M19: =SUM(M4:M18) -> 68 | N19: =SUM(N4:N18) -> 173 | O19: =SUM(O4:O18) -> 199 | P19: =SUM(P4:P18) -> 76

Sheet يناير-2026
C2: يناير-2026
C3: الدائرة | D3: رئيس الدائرة | E3: امين سر الجلسة | F3: عدد الطلبات المسجلة | G3: عدد الدعاوى المسجلة | H3: عدد الدعاوى المتداولة | I3: عدد الدعاوى المحكومة | J3: عدد الدعاوى المحالة | K3: نسبة الإنجاز | L3: عدد الدعاوى المرحلة | M3: عدد الدعاوى المحجوزة للحكم | N3: المتبقي للتداول | O3: احكام اليوم الواحد | P3: عدد الجلسات الالكترونية
C4: الدائرة الأولى تركات كلي | D4: د/ناصر عمران الكواري | E4: محمد رشدي | F4: 22 | G4: 13 | H4: 26 | I4: 6 | J4: 1 | K4: 0.34615385 | L4: 15 | M4: 2 | N4: 17 | O4: 0 | P4: 0
C5: الدائرة الثانية أسرة كلي | D5: محمد طايس الجميلي | E5: يوسف وحيد | F5: 59 | G5: 82 | H5: 95 | I5: 35 | J5: 1 | K5: 0.51578947 | L5: 44 | M5: 2 | N5: 46 | O5: 20 | P5: 5
C6: الدائرة الثالثةاستئناف | D6: دكتور عايض سعد القحطاني | E6: محمد على | F6: 16 | G6: 50 | H6: 38 | I6: 31 | J6: 1 | K6: 0.84210526 | L6: 5 | M6: 1 | N6: 6 | O6: 25 | P6: 2
C7: الدائرة الرابعة اسرة كلي | D7: موسي إبراهيم الهتمي | E7: سعيد الهاجري | F7: 42 | G7: 46 | H7: 72 | I7: 46 | J7: 2 | K7: 0.75 | L7: 17 | M7: 1 | N7: 18 | O7: 3 | P7: 0
C8: الدائرة الخامسة أسرة كلي | D8: حارب راشد المهندي | E8: محمد عبد الحليم | F8: 28 | G8: 43 | H8: 68 | I8: 42 | J8: 1 | K8: 0.67647059 | L8: 19 | M8: 3 | N8: 22 | O8: 2 | P8: 6
C9: الدائرة السادسة استئناف | D9: سعود محمد البوعينين | E9: محمد جمال | F9: 10 | G9: 46 | H9: 51 | I9: 29 | J9: 3 | K9: 0.66666667 | L9: 12 | M9: 5 | N9: 17 | O9: 1 | P9: 0
C10: الدائرة السابعة أسرة كلي | D10: محمد عبد الهادي الدوسري | E10: بدر الدين | F10: 55 | G10: 87 | H10: 107 | I10: 74 | J10: 0 | K10: 0.77570093 | L10: 24 | M10: 0 | N10: 24 | O10: 22 | P10: 17
C11: الدائرة الاولى جزئي | D11: سعد احمد السيلطي | E11: نعمة الله | F11: 25 | G11: 35 | H11: 69 | I11: 33 | J11: 3 | K11: 0.5942029 | L11: 7 | M11: 21 | N11: 28 | O11: 1 | P11: 0
C12: الدائرة الثانيةجزئي | D12: ماجد محمد العنزي | E12: ناصر العثمان | F12: 29 | G12: 36 | H12: 63 | I12: 42 | J12: 1 | K12: 0.73015873 | L12: 9 | M12: 8 | N12: 17 | O12: 4 | P12: 4
C13: الدائرة الثالثة جزئي | D13: محمد احمد صالح | E13: خالد العبدالله | F13: 35 | G13: 61 | H13: 68 | I13: 56 | J13: 1 | K13: 0.92647059 | L13: 5 | M13: 0 | N13: 5 | O13: 55 | P13: 2
C14: الدائرة الرابعة جزئي | D14: راجي جعفر سيد | E14: سارة الهاجري | F14: 18 | G14: 57 | H14: 60 | I14: 47 | J14: 0 | K14: 0.85 | L14: 9 | M14: 0 | N14: 9 | O14: 45 | P14: 0
C15: الدائرة الخامسة قاصرين | D15: ابراهيم غصاب العدوي | E15: غالية الحبشي | F15: 6 | G15: 25 | H15: 32 | I15: 22 | J15: 0 | K15: 0.75 | L15: 6 | M15: 2 | N15: 8 | O15: 1 | P15: 0
... C18: الدائرة التاسعة تركات | D18: على خالد الانصاري | E18: محمود عساف | F18: 9 | G18: 2 | H18: 12 | I18: 4 | J18: 0 | K18: 0.41666667 | L18: 6 | M18: 1 | N18: 7 | O18: 0 | P18: 0
C19: المجموع | F19: =SUM(F4:F18) -> 408 | G19: =SUM(G4:G18) -> 654 | H19: =SUM(H4:H18) -> 876 | I19: =SUM(I4:I18) -> 546 | J19: =SUM(J4:J18) -> 18 | K19: 0.72 | L19: =SUM(L4:L18) -> 194 | M19: =SUM(M4:M18) -> 52 | N19: =SUM(N4:N18) -> 246 | O19: =SUM(O4:O18) -> 211 | P19: =SUM(P4:P18) -> 53

Sheet فبراير2026
C2: فبراير -2026
C3: الدائرة | D3: رئيس الدائرة | E3: امين سر الجلسة | F3: عدد الطلبات المسجلة | G3: عدد الدعاوى المسجلة | H3: عدد الدعاوى المتداولة | I3: عدد الدعاوى المحكومة | J3: عدد الدعاوى المحالة | K3: نسبة الإنجاز | L3: عدد الدعاوى المرحلة | M3: عدد الدعاوى المحجوزة للحكم | N3: المتبقي للتداول | O3: احكام اليوم الواحد | P3: عدد الجلسات الالكترونية
C4: الدائرة الأولى تركات كلي | D4: د/ناصر عمران الكواري | E4: محمد رشدي | F4: 20 | G4: 9 | H4: 27 | I4: 9 | J4: 1 | K4: 0.37 | L4: 16 | M4: 1 | N4: 17 | O4: 0 | P4: 0
C5: الدائرة الثانية أسرة كلي | D5: محمد طايس الجميلي | E5: يوسف وحيد | F5: 63 | G5: 72 | H5: 122 | I5: 55 | J5: 18 | K5: 0.6 | L5: 6 | M5: 43 | N5: 49 | O5: 27 | P5: 8
C6: الدائرة الثالثةاستئناف | D6: دكتور عايض سعد القحطاني | E6: محمد على | F6: 9 | G6: 42 | H6: 48 | I6: 35 | J6: 0 | K6: 0.73 | L6: 13 | M6: 0 | N6: 13 | O6: 19 | P6: 9
C7: الدائرة الرابعة اسرة كلي | D7: موسي إبراهيم الهتمي | E7: سعيد الهاجري | F7: 33 | G7: 43 | H7: 64 | I7: 34 | J7: 5 | K7: 0.61 | L7: 25 | M7: 0 | N7: 25 | O7: 3 | P7: 0
C8: الدائرة الخامسة أسرة كلي | D8: حارب راشد المهندي | E8: محمد عبد الحليم | F8: 22 | G8: 38 | H8: 59 | I8: 39 | J8: 5 | K8: 0.75 | L8: 14 | M8: 1 | N8: 15 | O8: 4 | P8: 8
C9: الدائرة السادسة استئناف | D9: سعود محمد البوعينين | E9: محمد جمال | F9: 13 | G9: 43 | H9: 67 | I9: 39 | J9: 2 | K9: 0.61 | L9: 10 | M9: 16 | N9: 26 | O9: 0 | P9: 0
C10: الدائرة السابعة أسرة كلي | D10: محمد عبد الهادي الدوسري | E10: بدر الدين | F10: 72 | G10: 69 | H10: 104 | I10: 75 | J10: 9 | K10: 0.81 | L10: 17 | M10: 3 | N10: 20 | O10: 25 | P10: 21
C11: الدائرة الاولى جزئي | D11: سعد احمد السيلطي | E11: نعمة الله | F11: 22 | G11: 36 | H11: 68 | I11: 37 | J11: 3 | K11: 0.59 | L11: 0 | M11: 28 | N11: 28 | O11: 2 | P11: 0
C12: الدائرة الثانيةجزئي | D12: ماجد محمد العنزي | E12: ناصر العثمان | F12: 20 | G12: 37 | H12: 58 | I12: 40 | J12: 5 | K12: 0.78 | L12: 7 | M12: 6 | N12: 13 | O12: 5 | P12: 7
C13: الدائرة الثالثة جزئي | D13: محمد احمد صالح | E13: خالد العبدالله | F13: 29 | G13: 47 | H13: 59 | I13: 55 | J13: 2 | K13: 0.97 | L13: 2 | M13: 0 | N13: 2 | O13: 55 | P13: 2
C14: الدائرة الرابعة جزئي | D14: راجي جعفر سيد | E14: سارة الهاجري | F14: 37 | G14: 47 | H14: 62 | I14: 59 | J14: 2 | K14: 0.98 | L14: 1 | M14: 0 | N14: 1 | O14: 59 | P14: 6
C15: الدائرة الخامسة قاصرين | D15: ابراهيم غصاب العدوي | E15: غالية الحبشي | F15: 18 | G15: 21 | H15: 33 | I15: 24 | J15: 0 | K15: 0.73 | L15: 9 | M15: 0 | N15: 9 | O15: 4 | P15: 0
... C18: الدائرة التاسعة تركات | D18: على خالد الانصاري | E18: محمود عساف | F18: 3 | G18: 4 | H18: 11 | I18: 2 | J18: 0 | K18: 0.18 | L18: 7 | M18: 2 | N18: 9 | O18: 0 | P18: 0
C19: المجموع | F19: =SUM(F4:F18) -> 394 | G19: =SUM(G4:G18) -> 571 | H19: =SUM(H4:H18) -> 875 | I19: =SUM(I4:I18) -> 561 | J19: =SUM(J4:J18) -> 65 | K19: 0.72 | L19: =SUM(L4:L18) -> 144 | M19: =SUM(M4:M18) -> 105 | N19: =SUM(N4:N18) -> 249 | O19: =SUM(O4:O18) -> 237 | P19: =SUM(P4:P18) -> 76

Sheet مارس 2026
C2: مارس -2026
C3: الدائرة | D3: رئيس الدائرة | E3: امين سر الجلسة | F3: عدد الطلبات المسجلة | G3: عدد الدعاوى المسجلة | H3: عدد الدعاوى المتداولة | I3: عدد الدعاوى المحكومة | J3: الاحكام المتنوعه (احالة+شطب+وقف) | K3: نسبة الإنجاز | L3: عدد الدعاوى المرحلة | M3: عدد الدعاوى المحجوزة للحكم | N3: المتبقي للتداول | O3: احكام اليوم الواحد | P3: عدد الجلسات الالكترونية
C4: الدائرة الأولى تركات كلي | D4: د/ناصر عمران الكواري | E4: محمد رشدي | F4: 11 | G4: 5 | H4: 26 | I4: 6 | J4: 0 | K4: 0.23076923 | L4: 18 | M4: 2 | N4: 20 | O4: 0 | P4: 0
C5: الدائرة الثانية أسرة كلي | D5: محمد طايس الجميلي | E5: يوسف وحيد | F5: 47 | G5: 47 | H5: 107 | I5: 46 | J5: 6 | K5: 0.48598131 | L5: 48 | M5: 7 | N5: 55 | O5: 19 | P5: 137
C6: الدائرة الثالثةاستئناف | D6: دكتور عايض سعد القحطاني | E6: محمد على | F6: 14 | G6: 34 | H6: 55 | I6: 52 | J6: 0 | K6: 0.94545455 | L6: 3 | M6: 0 | N6: 3 | O6: 34 | P6: 64
C7: الدائرة الرابعة اسرة كلي | D7: موسي إبراهيم الهتمي | E7: سعيد الهاجري | F7: 23 | G7: 29 | H7: 61 | I7: 41 | J7: 2 | K7: 0.70491803 | L7: 18 | M7: 0 | N7: 18 | O7: 4 | P7: 49
C8: الدائرة الخامسة أسرة كلي | D8: حارب راشد المهندي | E8: محمد عبد الحليم | F8: 23 | G8: 26 | H8: 49 | I8: 28 | J8: 0 | K8: 0.57142857 | L8: 21 | M8: 0 | N8: 21 | O8: 5 | P8: 55
C9: الدائرة السادسة استئناف | D9: سعود محمد البوعينين | E9: محمد جمال | F9: 13 | G9: 24 | H9: 56 | I9: 31 | J9: 4 | K9: 0.625 | L9: 8 | M9: 13 | N9: 21 | O9: 0 | P9: 52
C10: الدائرة السابعة أسرة كلي | D10: محمد عبد الهادي الدوسري | E10: بدر الدين | F10: 27 | G10: 47 | H10: 72 | I10: 34 | J10: 3 | K10: 0.51388889 | L10: 29 | M10: 6 | N10: 35 | O10: 5 | P10: 88
C11: الدائرة الاولى جزئي | D11: سعد احمد السيلطي | E11: نعمة الله | F11: 18 | G11: 22 | H11: 51 | I11: 5 | J11: 2 | K11: 0.1372549 | L11: 31 | M11: 13 | N11: 44 | O11: 2 | P11: 41
C12: الدائرة الثانيةجزئي | D12: ماجد محمد العنزي | E12: ناصر العثمان | F12: 14 | G12: 20 | H12: 31 | I12: 17 | J12: 3 | K12: 0.64516129 | L12: 8 | M12: 3 | N12: 11 | O12: 2 | P12: 22
C13: الدائرة الثالثة جزئي | D13: محمد احمد صالح | E13: خالد العبدالله | F13: 8 | G13: 32 | H13: 29 | I13: 28 | J13: 0 | K13: 0.96551724 | L13: 1 | M13: 0 | N13: 1 | O13: 28 | P13: 31
C14: الدائرة الرابعة جزئي | D14: راجي جعفر سيد | E14: سارة الهاجري | F14: 11 | G14: 28 | H14: 28 | I14: 19 | J14: 0 | K14: 0.67857143 | L14: 9 | M14: 0 | N14: 9 | O14: 19 | P14: 32
C15: الدائرة الخامسة قاصرين | D15: ابراهيم غصاب العدوي | E15: غالية الحبشي | F15: 6 | G15: 12 | H15: 18 | I15: 11 | J15: 2 | K15: 0.72222222 | L15: 5 | M15: 0 | N15: 5 | O15: 4 | P15: 4
... C18: الدائرة التاسعة تركات | D18: على خالد الانصاري | E18: محمود عساف | F18: 7 | G18: 1 | H18: 11 | I18: 4 | J18: 0 | K18: 0.36363636 | L18: 7 | M18: 0 | N18: 7 | O18: 0 | P18: 3
C19: المجموع | F19: =SUM(F4:F18) -> 258 | G19: =SUM(G4:G18) -> 367 | H19: =SUM(H4:H18) -> 664 | I19: =SUM(I4:I18) -> 341 | J19: =SUM(J4:J18) -> 31 | K19: 0.56 | L19: =SUM(L4:L18) -> 236 | M19: =SUM(M4:M18) -> 56 | N19: =SUM(N4:N18) -> 292 | O19: =SUM(O4:O18) -> 130 | P19: =SUM(P4:P18) -> 647

Sheet ابريل -2026
C2: ابريل -2026
C3: الدائرة | D3: رئيس الدائرة | E3: امين سر الجلسة | F3: عدد الطلبات المسجلة | G3: عدد الدعاوى المسجلة | H3: عدد الدعاوى المتداولة | I3: عدد الدعاوى المحكومة | J3: الاحكام المتنوعه (احالة+شطب+وقف) | K3: نسبة الإنجاز | L3: عدد الدعاوى المرحلة | M3: عدد الدعاوى المحجوزة للحكم | N3: المتبقي للتداول | O3: احكام اليوم الواحد | P3: عدد الجلسات الالكترونية
C4: الدائرة الأولى تركات كلي | D4: د/ناصر عمران الكواري | E4: محمد رشدي | F4: 44 | G4: 13 | H4: 32 | I4: 17 | J4: 0 | K4: 0.53125 | L4: 12 | M4: 3 | N4: 15 | O4: 0 | P4: 0
C5: الدائرة الثانية أسرة كلي | D5: محمد طايس الجميلي | E5: يوسف وحيد | F5: 121 | G5: 89 | H5: 139 | I5: 87 | J5: 10 | K5: 0.69064748 | L5: 40 | M5: 3 | N5: 43 | O5: 33 | P5: 169
C6: الدائرة الثالثةاستئناف | D6: دكتور عايض سعد القحطاني | E6: محمد على | F6: 21 | G6: 22 | H6: 22 | I6: 21 | J6: 0 | K6: 0.95454545 | L6: 1 | M6: 0 | N6: 1 | O6: 21 | P6: 26
C7: الدائرة الرابعة اسرة كلي | D7: موسي إبراهيم الهتمي | E7: سعيد الهاجري | F7: 66 | G7: 54 | H7: 61 | I7: 42 | J7: 3 | K7: 0.73770492 | L7: 16 | M7: 0 | N7: 16 | O7: 2 | P7: 40
C8: الدائرة الخامسة أسرة كلي | D8: حارب راشد المهندي | E8: محمد عبد الحليم | F8: 58 | G8: 54 | H8: 66 | I8: 36 | J8: 2 | K8: 0.57575758 | L8: 19 | M8: 9 | N8: 28 | O8: 4 | P8: 63
C9: الدائرة السادسة استئناف | D9: سعود محمد البوعينين | E9: محمد جمال | F9: 12 | G9: 23 | H9: 49 | I9: 37 | J9: 2 | K9: 0.79591837 | L9: 6 | M9: 4 | N9: 10 | O9: 0 | P9: 41
C10: الدائرة السابعة أسرة كلي | D10: محمد عبد الهادي الدوسري | E10: بدر الدين | F10: 73 | G10: 90 | H10: 115 | I10: 77 | J10: 6 | K10: 0.72173913 | L10: 29 | M10: 3 | N10: 32 | O10: 24 | P10: 120
C11: الدائرة الاولى جزئي | D11: سعد احمد السيلطي | E11: نعمة الله | F11: 67 | G11: 43 | H11: 85 | I11: 41 | J11: 5 | K11: 0.54117647 | L11: 24 | M11: 15 | N11: 39 | O11: 2 | P11: 59
C12: الدائرة الثانيةجزئي | D12: ماجد محمد العنزي | E12: ناصر العثمان | F12: 67 | G12: 49 | H12: 61 | I12: 30 | J12: 2 | K12: 0.52459016 | L12: 14 | M12: 15 | N12: 29 | O12: 5 | P12: 48
C13: الدائرة الثالثة جزئي | D13: محمد احمد صالح | E13: خالد العبدالله | F13: 47 | G13: 56 | H13: 55 | I13: 47 | J13: 5 | K13: 0.94545455 | L13: 3 | M13: 0 | N13: 3 | O13: 47 | P13: 44
C14: الدائرة الرابعة جزئي | D14: راجي جعفر سيد | E14: سارة الهاجري | F14: 41 | G14: 53 | H14: 61 | I14: 60 | J14: 1 | K14: 1 | L14: 0 | M14: 0 | N14: 0 | O14: 60 | P14: 57
C15: الدائرة الخامسة قاصرين | D15: ابراهيم غصاب العدوي | E15: غالية الحبشي | F15: 23 | G15: 37 | H15: 35 | I15: 27 | J15: 0 | K15: 0.77142857 | L15: 6 | M15: 2 | N15: 8 | O15: 12 | P15: 12
... C18: الدائرة التاسعة تركات | D18: على خالد الانصاري | E18: محمود عساف | F18: 17 | G18: 6 | H18: 11 | I18: 4 | J18: 0 | K18: 0.36363636 | L18: 5 | M18: 2 | N18: 7 | O18: 0 | P18: 0
C19: المجموع | F19: =SUM(F4:F18) -> 755 | G19: =SUM(G4:G18) -> 673 | H19: =SUM(H4:H18) -> 917 | I19: =SUM(I4:I18) -> 612 | J19: =SUM(J4:J18) -> 44 | K19: 0.7 | L19: =SUM(L4:L18) -> 204 | M19: =SUM(M4:M18) -> 68 | N19: =SUM(N4:N18) -> 272 | O19: =SUM(O4:O18) -> 255 | P19: =SUM(P4:P18) -> 790

Sheet مايو -2026 
C2: مايو-2026
C3: الدائرة | D3: رئيس الدائرة | E3: امين سر الجلسة | F3: عدد الطلبات المسجلة | G3: عدد الدعاوى المسجلة | H3: عدد الدعاوى المتداولة | I3: عدد الدعاوى المحكومة | J3: الاحكام المتنوعه (احالة+شطب+وقف) | K3: نسبة الإنجاز | L3: عدد الدعاوى المرحلة | M3: عدد الدعاوى المحجوزة للحكم | N3: المتبقي للتداول | O3: احكام اليوم الواحد | P3: عدد الجلسات الالكترونية
C4: الدائرة الأولى تركات كلي | D4: د/ناصر عمران الكواري | E4: محمد رشدي
C5: الدائرة الثانية أسرة كلي | D5: محمد طايس الجميلي | E5: يوسف وحيد
C6: الدائرة الثالثةاستئناف | D6: دكتور عايض سعد القحطاني | E6: محمد على
C7: الدائرة الرابعة اسرة كلي | D7: موسي إبراهيم الهتمي | E7: سعيد الهاجري
C8: الدائرة الخامسة أسرة كلي | D8: حارب راشد المهندي | E8: محمد عبد الحليم
C9: الدائرة السادسة استئناف | D9: سعود محمد البوعينين | E9: محمد جمال
C10: الدائرة السابعة أسرة كلي | D10: محمد عبد الهادي الدوسري | E10: بدر الدين
C11: الدائرة الاولى جزئي | D11: سعد احمد السيلطي | E11: نعمة الله
C12: الدائرة الثانيةجزئي | D12: ماجد محمد العنزي | E12: ناصر العثمان
C13: الدائرة الثالثة جزئي | D13: محمد احمد صالح | E13: خالد العبدالله
C14: الدائرة الرابعة جزئي | D14: راجي جعفر سيد | E14: سارة الهاجري
C15: الدائرة الخامسة قاصرين | D15: ابراهيم غصاب العدوي | E15: غالية الحبشي
... C18: الدائرة التاسعة تركات | D18: على خالد الانصاري | E18: محمود عساف
C19: المجموع | F19: =SUM(F4:F18) -> 0 | G19: =SUM(G4:G18) -> 0 | H19: =SUM(H4:H18) -> 0 | I19: =SUM(I4:I18) -> 0 | J19: =SUM(J4:J18) -> 0 | K19: 0.7 | L19: =SUM(L4:L18) -> 0 | M19: =SUM(M4:M18) -> 0 | N19: =SUM(N4:N18) -> 0 | O19: =SUM(O4:O18) -> 0 | P19: =SUM(P4:P18) -> 0

Sheet يونيو -2026
C2: يونيو -2026
C3: الدائرة | D3: رئيس الدائرة | E3: امين سر الجلسة | F3: عدد الطلبات المسجلة | G3: عدد الدعاوى المسجلة | H3: عدد الدعاوى المتداولة | I3: عدد الدعاوى المحكومة | J3: الاحكام المتنوعه (احالة+شطب+وقف) | K3: نسبة الإنجاز | L3: عدد الدعاوى المرحلة | M3: عدد الدعاوى المحجوزة للحكم | N3: المتبقي للتداول | O3: احكام اليوم الواحد | P3: عدد الجلسات الالكترونية
C4: الدائرة الأولى تركات كلي | D4: د/ناصر عمران الكواري | E4: محمد رشدي
C5: الدائرة الثانية أسرة كلي | D5: محمد طايس الجميلي | E5: يوسف وحيد
C6: الدائرة الثالثةاستئناف | D6: دكتور عايض سعد القحطاني | E6: محمد على
C7: الدائرة الرابعة اسرة كلي | D7: موسي إبراهيم الهتمي | E7: سعيد الهاجري
C8: الدائرة الخامسة أسرة كلي | D8: حارب راشد المهندي | E8: محمد عبد الحليم
C9: الدائرة السادسة استئناف | D9: سعود محمد البوعينين | E9: محمد جمال
C10: الدائرة السابعة أسرة كلي | D10: محمد عبد الهادي الدوسري | E10: بدر الدين
C11: الدائرة الاولى جزئي | D11: سعد احمد السيلطي | E11: نعمة الله
C12: الدائرة الثانيةجزئي | D12: ماجد محمد العنزي | E12: ناصر العثمان
C13: الدائرة الثالثة جزئي | D13: محمد احمد صالح | E13: خالد العبدالله
C14: الدائرة الرابعة جزئي | D14: راجي جعفر سيد | E14: سارة الهاجري
C15: الدائرة الخامسة قاصرين | D15: ابراهيم غصاب العدوي | E15: غالية الحبشي
... C18: الدائرة التاسعة تركات | D18: على خالد الانصاري | E18: محمود عساف
C19: المجموع | F19: =SUM(F4:F18) -> 0 | G19: =SUM(G4:G18) -> 0 | H19: =SUM(H4:H18) -> 0 | I19: =SUM(I4:I18) -> 0 | J19: =SUM(J4:J18) -> 0 | K19: 0.7 | L19: =SUM(L4:L18) -> 0 | M19: =SUM(M4:M18) -> 0 | N19: =SUM(N4:N18) -> 0 | O19: =SUM(O4:O18) -> 0 | P19: =SUM(P4:P18) -> 0

Sheet يوليو -2026
C2: يوليو -2026
C3: الدائرة | D3: رئيس الدائرة | E3: امين سر الجلسة | F3: عدد الطلبات المسجلة | G3: عدد الدعاوى المسجلة | H3: عدد الدعاوى المتداولة | I3: عدد الدعاوى المحكومة | J3: الاحكام المتنوعه (احالة+شطب+وقف) | K3: نسبة الإنجاز | L3: عدد الدعاوى المرحلة | M3: عدد الدعاوى المحجوزة للحكم | N3: المتبقي للتداول | O3: احكام اليوم الواحد | P3: عدد الجلسات الالكترونية
C4: الدائرة الأولى تركات كلي | D4: د/ناصر عمران الكواري | E4: محمد رشدي
C5: الدائرة الثانية أسرة كلي | D5: محمد طايس الجميلي | E5: يوسف وحيد
C6: الدائرة الثالثةاستئناف | D6: دكتور عايض سعد القحطاني | E6: محمد على
C7: الدائرة الرابعة اسرة كلي | D7: موسي إبراهيم الهتمي | E7: سعيد الهاجري
C8: الدائرة الخامسة أسرة كلي | D8: حارب راشد المهندي | E8: محمد عبد الحليم
C9: الدائرة السادسة استئناف | D9: سعود محمد البوعينين | E9: محمد جمال
C10: الدائرة السابعة أسرة كلي | D10: محمد عبد الهادي الدوسري | E10: بدر الدين
C11: الدائرة الاولى جزئي | D11: سعد احمد السيلطي | E11: نعمة الله
C12: الدائرة الثانيةجزئي | D12: ماجد محمد العنزي | E12: ناصر العثمان
C13: الدائرة الثالثة جزئي | D13: محمد احمد صالح | E13: خالد العبدالله
C14: الدائرة الرابعة جزئي | D14: راجي جعفر سيد | E14: سارة الهاجري
C15: الدائرة الخامسة قاصرين | D15: ابراهيم غصاب العدوي | E15: غالية الحبشي
... C18: الدائرة التاسعة تركات | D18: على خالد الانصاري | E18: محمود عساف
C19: المجموع | F19: =SUM(F4:F18) -> 0 | G19: =SUM(G4:G18) -> 0 | H19: =SUM(H4:H18) -> 0 | I19: =SUM(I4:I18) -> 0 | J19: =SUM(J4:J18) -> 0 | K19: 0.7 | L19: =SUM(L4:L18) -> 0 | M19: =SUM(M4:M18) -> 0 | N19: =SUM(N4:N18) -> 0 | O19: =SUM(O4:O18) -> 0 | P19: =SUM(P4:P18) -> 0

Sheet أغسطس -2026
C2: أغسطس-2026
C3: الدائرة | D3: رئيس الدائرة | E3: امين سر الجلسة | F3: عدد الطلبات المسجلة | G3: عدد الدعاوى المسجلة | H3: عدد الدعاوى المتداولة | I3: عدد الدعاوى المحكومة | J3: الاحكام المتنوعه (احالة+شطب+وقف) | K3: نسبة الإنجاز | L3: عدد الدعاوى المرحلة | M3: عدد الدعاوى المحجوزة للحكم | N3: المتبقي للتداول | O3: احكام اليوم الواحد | P3: عدد الجلسات الالكترونية
C4: الدائرة الأولى تركات كلي | D4: د/ناصر عمران الكواري | E4: محمد رشدي
C5: الدائرة الثانية أسرة كلي | D5: محمد طايس الجميلي | E5: يوسف وحيد
C6: الدائرة الثالثةاستئناف | D6: دكتور عايض سعد القحطاني | E6: محمد على
C7: الدائرة الرابعة اسرة كلي | D7: موسي إبراهيم الهتمي | E7: سعيد الهاجري
C8: الدائرة الخامسة أسرة كلي | D8: حارب راشد المهندي | E8: محمد عبد الحليم
C9: الدائرة السادسة استئناف | D9: سعود محمد البوعينين | E9: محمد جمال
C10: الدائرة السابعة أسرة كلي | D10: محمد عبد الهادي الدوسري | E10: بدر الدين
C11: الدائرة الاولى جزئي | D11: سعد احمد السيلطي | E11: نعمة الله
C12: الدائرة الثانيةجزئي | D12: ماجد محمد العنزي | E12: ناصر العثمان
C13: الدائرة الثالثة جزئي | D13: محمد احمد صالح | E13: خالد العبدالله
C14: الدائرة الرابعة جزئي | D14: راجي جعفر سيد | E14: سارة الهاجري
C15: الدائرة الخامسة قاصرين | D15: ابراهيم غصاب العدوي | E15: غالية الحبشي
... C18: الدائرة التاسعة تركات | D18: على خالد الانصاري | E18: محمود عساف
C19: المجموع | F19: =SUM(F4:F18) -> 0 | G19: =SUM(G4:G18) -> 0 | H19: =SUM(H4:H18) -> 0 | I19: =SUM(I4:I18) -> 0 | J19: =SUM(J4:J18) -> 0 | K19: 0.7 | L19: =SUM(L4:L18) -> 0 | M19: =SUM(M4:M18) -> 0 | N19: =SUM(N4:N18) -> 0 | O19: =SUM(O4:O18) -> 0 | P19: =SUM(P4:P18) -> 0

Sheet سبتمبر -2026
C2: سبتمبر -2026
C3: الدائرة | D3: رئيس الدائرة | E3: امين سر الجلسة | F3: عدد الطلبات المسجلة | G3: عدد الدعاوى المسجلة | H3: عدد الدعاوى المتداولة | I3: عدد الدعاوى المحكومة | J3: الاحكام المتنوعه (احالة+شطب+وقف) | K3: نسبة الإنجاز | L3: عدد الدعاوى المرحلة | M3: عدد الدعاوى المحجوزة للحكم | N3: المتبقي للتداول | O3: احكام اليوم الواحد | P3: عدد الجلسات الالكترونية
C4: الدائرة الأولى تركات كلي | D4: د/ناصر عمران الكواري | E4: محمد رشدي
C5: الدائرة الثانية أسرة كلي | D5: محمد طايس الجميلي | E5: يوسف وحيد
C6: الدائرة الثالثةاستئناف | D6: دكتور عايض سعد القحطاني | E6: محمد على
C7: الدائرة الرابعة اسرة كلي | D7: موسي إبراهيم الهتمي | E7: سعيد الهاجري
C8: الدائرة الخامسة أسرة كلي | D8: حارب راشد المهندي | E8: محمد عبد الحليم
C9: الدائرة السادسة استئناف | D9: سعود محمد البوعينين | E9: محمد جمال
C10: الدائرة السابعة أسرة كلي | D10: محمد عبد الهادي الدوسري | E10: بدر الدين
C11: الدائرة الاولى جزئي | D11: سعد احمد السيلطي | E11: نعمة الله
C12: الدائرة الثانيةجزئي | D12: ماجد محمد العنزي | E12: ناصر العثمان
C13: الدائرة الثالثة جزئي | D13: محمد احمد صالح | E13: خالد العبدالله
C14: الدائرة الرابعة جزئي | D14: راجي جعفر سيد | E14: سارة الهاجري
C15: الدائرة الخامسة قاصرين | D15: ابراهيم غصاب العدوي | E15: غالية الحبشي
... C18: الدائرة التاسعة تركات | D18: على خالد الانصاري | E18: محمود عساف
C19: المجموع | F19: =SUM(F4:F18) -> 0 | G19: =SUM(G4:G18) -> 0 | H19: =SUM(H4:H18) -> 0 | I19: =SUM(I4:I18) -> 0 | J19: =SUM(J4:J18) -> 0 | K19: 0.7 | L19: =SUM(L4:L18) -> 0 | M19: =SUM(M4:M18) -> 0 | N19: =SUM(N4:N18) -> 0 | O19: =SUM(O4:O18) -> 0 | P19: =SUM(P4:P18) -> 0

Sheet أكتوبر -2026 
C2: أكتوبر -2026
C3: الدائرة | D3: رئيس الدائرة | E3: امين سر الجلسة | F3: عدد الطلبات المسجلة | G3: عدد الدعاوى المسجلة | H3: عدد الدعاوى المتداولة | I3: عدد الدعاوى المحكومة | J3: الاحكام المتنوعه (احالة+شطب+وقف) | K3: نسبة الإنجاز | L3: عدد الدعاوى المرحلة | M3: عدد الدعاوى المحجوزة للحكم | N3: المتبقي للتداول | O3: احكام اليوم الواحد | P3: عدد الجلسات الالكترونية
C4: الدائرة الأولى تركات كلي | D4: د/ناصر عمران الكواري | E4: محمد رشدي
C5: الدائرة الثانية أسرة كلي | D5: محمد طايس الجميلي | E5: يوسف وحيد
C6: الدائرة الثالثةاستئناف | D6: دكتور عايض سعد القحطاني | E6: محمد على
C7: الدائرة الرابعة اسرة كلي | D7: موسي إبراهيم الهتمي | E7: سعيد الهاجري
C8: الدائرة الخامسة أسرة كلي | D8: حارب راشد المهندي | E8: محمد عبد الحليم
C9: الدائرة السادسة استئناف | D9: سعود محمد البوعينين | E9: محمد جمال
C10: الدائرة السابعة أسرة كلي | D10: محمد عبد الهادي الدوسري | E10: بدر الدين
C11: الدائرة الاولى جزئي | D11: سعد احمد السيلطي | E11: نعمة الله
C12: الدائرة الثانيةجزئي | D12: ماجد محمد العنزي | E12: ناصر العثمان
C13: الدائرة الثالثة جزئي | D13: محمد احمد صالح | E13: خالد العبدالله
C14: الدائرة الرابعة جزئي | D14: راجي جعفر سيد | E14: سارة الهاجري
C15: الدائرة الخامسة قاصرين | D15: ابراهيم غصاب العدوي | E15: غالية الحبشي
... C18: الدائرة التاسعة تركات | D18: على خالد الانصاري | E18: محمود عساف
C19: المجموع | F19: =SUM(F4:F18) -> 0 | G19: =SUM(G4:G18) -> 0 | H19: =SUM(H4:H18) -> 0 | I19: =SUM(I4:I18) -> 0 | J19: =SUM(J4:J18) -> 0 | K19: 0.7 | L19: =SUM(L4:L18) -> 0 | M19: =SUM(M4:M18) -> 0 | N19: =SUM(N4:N18) -> 0 | O19: =SUM(O4:O18) -> 0 | P19: =SUM(P4:P18) -> 0

Sheet نوفمبر -2026 
C2: نوفمبر -2026
C3: الدائرة | D3: رئيس الدائرة | E3: امين سر الجلسة | F3: عدد الطلبات المسجلة | G3: عدد الدعاوى المسجلة | H3: عدد الدعاوى المتداولة | I3: عدد الدعاوى المحكومة | J3: الاحكام المتنوعه (احالة+شطب+وقف) | K3: نسبة الإنجاز | L3: عدد الدعاوى المرحلة | M3: عدد الدعاوى المحجوزة للحكم | N3: المتبقي للتداول | O3: احكام اليوم الواحد | P3: عدد الجلسات الالكترونية
C4: الدائرة الأولى تركات كلي | D4: د/ناصر عمران الكواري | E4: محمد رشدي
C5: الدائرة الثانية أسرة كلي | D5: محمد طايس الجميلي | E5: يوسف وحيد
C6: الدائرة الثالثةاستئناف | D6: دكتور عايض سعد القحطاني | E6: محمد على
C7: الدائرة الرابعة اسرة كلي | D7: موسي إبراهيم الهتمي | E7: سعيد الهاجري
C8: الدائرة الخامسة أسرة كلي | D8: حارب راشد المهندي | E8: محمد عبد الحليم
C9: الدائرة السادسة استئناف | D9: سعود محمد البوعينين | E9: محمد جمال
C10: الدائرة السابعة أسرة كلي | D10: محمد عبد الهادي الدوسري | E10: بدر الدين
C11: الدائرة الاولى جزئي | D11: سعد احمد السيلطي | E11: نعمة الله
C12: الدائرة الثانيةجزئي | D12: ماجد محمد العنزي | E12: ناصر العثمان
C13: الدائرة الثالثة جزئي | D13: محمد احمد صالح | E13: خالد العبدالله
C14: الدائرة الرابعة جزئي | D14: راجي جعفر سيد | E14: سارة الهاجري
C15: الدائرة الخامسة قاصرين | D15: ابراهيم غصاب العدوي | E15: غالية الحبشي
... C18: الدائرة التاسعة تركات | D18: على خالد الانصاري | E18: محمود عساف
C19: المجموع | F19: =SUM(F4:F18) -> 0 | G19: =SUM(G4:G18) -> 0 | H19: =SUM(H4:H18) -> 0 | I19: =SUM(I4:I18) -> 0 | J19: =SUM(J4:J18) -> 0 | K19: 0.7 | L19: =SUM(L4:L18) -> 0 | M19: =SUM(M4:M18) -> 0 | N19: =SUM(N4:N18) -> 0 | O19: =SUM(O4:O18) -> 0 | P19: =SUM(P4:P18) -> 0

Sheet ديسمبر -2026  
C2: ديسمبر -2026
C3: الدائرة | D3: رئيس الدائرة | E3: امين سر الجلسة | F3: عدد الطلبات المسجلة | G3: عدد الدعاوى المسجلة | H3: عدد الدعاوى المتداولة | I3: عدد الدعاوى المحكومة | J3: الاحكام المتنوعه (احالة+شطب+وقف) | K3: نسبة الإنجاز | L3: عدد الدعاوى المرحلة | M3: عدد الدعاوى المحجوزة للحكم | N3: المتبقي للتداول | O3: احكام اليوم الواحد | P3: عدد الجلسات الالكترونية
C4: الدائرة الأولى تركات كلي | D4: د/ناصر عمران الكواري | E4: محمد رشدي
C5: الدائرة الثانية أسرة كلي | D5: محمد طايس الجميلي | E5: يوسف وحيد
C6: الدائرة الثالثةاستئناف | D6: دكتور عايض سعد القحطاني | E6: محمد على
C7: الدائرة الرابعة اسرة كلي | D7: موسي إبراهيم الهتمي | E7: سعيد الهاجري
C8: الدائرة الخامسة أسرة كلي | D8: حارب راشد المهندي | E8: محمد عبد الحليم
C9: الدائرة السادسة استئناف | D9: سعود محمد البوعينين | E9: محمد جمال
C10: الدائرة السابعة أسرة كلي | D10: محمد عبد الهادي الدوسري | E10: بدر الدين
C11: الدائرة الاولى جزئي | D11: سعد احمد السيلطي | E11: نعمة الله
C12: الدائرة الثانيةجزئي | D12: ماجد محمد العنزي | E12: ناصر العثمان
C13: الدائرة الثالثة جزئي | D13: محمد احمد صالح | E13: خالد العبدالله
C14: الدائرة الرابعة جزئي | D14: راجي جعفر سيد | E14: سارة الهاجري
C15: الدائرة الخامسة قاصرين | D15: ابراهيم غصاب العدوي | E15: غالية الحبشي
... C18: الدائرة التاسعة تركات | D18: على خالد الانصاري | E18: محمود عساف
C19: المجموع | F19: =SUM(F4:F18) -> 0 | G19: =SUM(G4:G18) -> 0 | H19: =SUM(H4:H18) -> 0 | I19: =SUM(I4:I18) -> 0 | J19: =SUM(J4:J18) -> 0 | K19: 0.7 | L19: =SUM(L4:L18) -> 0 | M19: =SUM(M4:M18) -> 0 | N19: =SUM(N4:N18) -> 0 | O19: =SUM(O4:O18) -> 0 | P19: =SUM(P4:P18) -> 0

Sheet بيانات_الفلتر
A1: الشهر | B1: الدائرة | C1: الطلبات المسجلة | D1: الدعاوى المسجلة | E1: المتداولة | F1: المحكومة | G1: نسبة الإنجاز | H1: المرحّلة | I1: المحجوزة | J1: المتبقي | K1: الطلبات | L1: المسجلة | M1: الجلسات الإلكترونية | N1: أحكام اليوم الواحد | O1: أحكام اليوم الواحد
A2: سبتمبر 2025 | B2: الدائرة الأولى تركات كلي | C2: 43 | D2: 16 | E2: 36 | F2: 17 | G2: 0.56 | H2: 10 | I2: 6 | J2: 16 | K2: 17 | L2: 15 | M2: 0 | N2: كل الشهور | O2: 0
A3: سبتمبر 2025 | B3: الدائرة الثانية أسرة كلي | C3: 134 | D3: 50 | E3: 138 | F3: 85 | G3: 0.72 | H3: 30 | I3: 9 | J3: 39 | K3: 48 | L3: 54 | M3: 5 | N3: سبتمبر 2025 | O3: 10
A4: سبتمبر 2025 | B4: الدائرة الثالثةاستئناف | C4: 36 | D4: 22 | E4: 74 | F4: 57 | G4: 0.78 | H4: 3 | I4: 13 | J4: 16 | K4: 6 | L4: 34 | M4: 3 | N4: أكتوبر 2025 | O4: 5
A5: سبتمبر 2025 | B5: الدائرة الرابعة اسرة كلي | C5: 105 | D5: 59 | E5: 158 | F5: 103 | G5: 0.75 | H5: 39 | I5: 0 | J5: 39 | K5: 26 | L5: 60 | M5: 0 | N5: نوفمبر 2025 | O5: 5
A6: سبتمبر 2025 | B6: الدائرة الخامسة أسرة كلي | C6: 116 | D6: 53 | E6: 162 | F6: 90 | G6: 0.71 | H6: 41 | I6: 6 | J6: 47 | K6: 61 | L6: 54 | M6: 3 | N6: ديسمبر 2025 | O6: 9
A7: سبتمبر 2025 | B7: الدائرة السادسة استئناف | C7: 1 | D7: 12 | E7: 17 | F7: 12 | G7: 1 | H7: 0 | I7: 0 | J7: 0 | K7: 10 | L7: 33 | M7: 0 | N7: يناير 2026 | O7: 3
A8: سبتمبر 2025 | B8: الدائرة السابعة أسرة كلي | C8: 70 | D8: 58 | E8: 122 | F8: 90 | G8: 0.85 | H8: 18 | I8: 0 | J8: 18 | K8: 47 | L8: 103 | M8: 4 | N8: فبراير 2026 | O8: 25
A9: سبتمبر 2025 | B9: الدائرة الاولى جزئي | C9: 63 | D9: 29 | E9: 94 | F9: 63 | G9: 0.68 | H9: 25 | I9: 5 | J9: 30 | K9: 14 | L9: 42 | M9: 0 | N9: مارس 2026 | O9: 19
A10: سبتمبر 2025 | B10: الدائرة الثانيةجزئي | C10: 42 | D10: 36 | E10: 55 | F10: 36 | G10: 0.69 | H10: 10 | I10: 7 | J10: 17 | K10: 59 | L10: 41 | M10: 1 | N10: أبريل 2026 | O10: 9
A11: سبتمبر 2025 | B11: الدائرة الثالثة جزئي | C11: 64 | D11: 63 | E11: 80 | F11: 66 | G11: 0.91 | H11: 7 | I11: 0 | J11: 7 | K11: 43 | L11: 59 | M11: 0 | N11: مايو 2026 | O11: 63
A12: سبتمبر 2025 | B12: الدائرة الرابعة جزئي | C12: 90 | D12: 37 | E12: 132 | F12: 106 | G12: 0.89 | H12: 14 | I12: 0 | J12: 14 | K12: 35 | L12: 57 | M12: 0 | N12: يونيو 2026 | O12: 95
A13: سبتمبر 2025 | B13: الدائرة الخامسة قاصرين | C13: 24 | D13: 24 | E13: 69 | F13: 48 | G13: 0.84 | H13: 9 | I13: 2 | J13: 11 | K13: 13 | L13: 28 | M13: 0 | N13: يوليو 2026 | O13: 8
... A18: أكتوبر 2025 | B18: الدائرة الثانية أسرة كلي | C18: 119 | D18: 86 | E18: 117 | F18: 55 | G18: 0.5 | H18: 58 | I18: 17 | J18: 41 | K18: 59 | L18: 82 | M18: 20 | N18: ديسمبر 2026 | O18: 16
A19: أكتوبر 2025 | B19: الدائرة الثالثةاستئناف | C19: 34 | D19: 53 | E19: 65 | F19: 38 | G19: 0.62 | H19: 25 | I19: 12 | J19: 13 | K19: 16 | L19: 50 | M19: 7 | O19: 10
A20: أكتوبر 2025 | B20: الدائرة الرابعة اسرة كلي | C20: 79 | D20: 45 | E20: 95 | F20: 61 | G20: 0.83 | H20: 16 | I20: 0 | J20: 16 | K20: 42 | L20: 46 | M20: 5 | O20: 1
A21: أكتوبر 2025 | B21: الدائرة الخامسة أسرة كلي | C21: 80 | D21: 54 | E21: 98 | F21: 61 | G21: 0.66 | H21: 33 | I21: 1 | J21: 32 | K21: 28 | L21: 43 | M21: 12 | O21: 2
A22: أكتوبر 2025 | B22: الدائرة السادسة استئناف | C22: 15 | D22: 48 | E22: 35 | F22: 17 | G22: 0.6 | H22: 14 | I22: 7 | J22: 7 | K22: 10 | L22: 46 | M22: 0 | O22: 0
A23: أكتوبر 2025 | B23: الدائرة السابعة أسرة كلي | C23: 85 | D23: 75 | E23: 90 | F23: 60 | G23: 0.81 | H23: 17 | I23: 0 | J23: 17 | K23: 55 | L23: 87 | M23: 4 | O23: 17
A24: أكتوبر 2025 | B24: الدائرة الاولى جزئي | C24: 60 | D24: 40 | E24: 66 | F24: 33 | G24: 0.5 | H24: 33 | I24: 24 | J24: 9 | K24: 25 | L24: 35 | M24: 0 | O24: 21
A25: أكتوبر 2025 | B25: الدائرة الثانيةجزئي | C25: 41 | D25: 38 | E25: 56 | F25: 26 | G25: 0.59 | H25: 23 | I25: 18 | J25: 5 | K25: 29 | L25: 36 | M25: 2 | O25: 1
A26: أكتوبر 2025 | B26: الدائرة الثالثة جزئي | C26: 50 | D26: 45 | E26: 52 | F26: 43 | G26: 0.92 | H26: 4 | I26: 0 | J26: 4 | K26: 35 | L26: 61 | M26: 6 | O26: 43
A27: أكتوبر 2025 | B27: الدائرة الرابعة جزئي | C27: 60 | D27: 44 | E27: 64 | F27: 53 | G27: 0.88 | H27: 8 | I27: 0 | J27: 8 | K27: 18 | L27: 57 | M27: 2 | O27: 47
A28: أكتوبر 2025 | B28: الدائرة الخامسة قاصرين | C28: 22 | D28: 41 | E28: 48 | F28: 34 | G28: 0.73 | H28: 13 | I28: 0 | J28: 13 | K28: 6 | L28: 25 | M28: 0 | O28: 13
A29: أكتوبر 2025 | B29: الدائرة السادسة جزئي | C29: 43 | D29: 37 | E29: 50 | F29: 25 | G29: 0.62 | H29: 19 | I29: 9 | J29: 10 | K29: 31 | L29: 34 | M29: 9 | O29: 3
A30: أكتوبر 2025 | B30: الدائرة الثامنة جزئي | C30: 24 | D30: 38 | E30: 73 | F30: 61 | G30: 0.9 | H30: 7 | I30: 0 | J30: 7 | K30: 23 | L30: 37 | M30: 0 | O30: 36
... A121: أبريل 2026 | B121: الدائرة التاسعة تركات | C121: 17 | D121: 6 | E121: 11 | F121: 4 | G121: 0.363636 | H121: 5 | I121: 2 | J121: 7 | K121: 21 | L121: 4 | M121: 0 | O121: 0
A122: مايو 2026 | B122: الدائرة الأولى تركات كلي | C122: 0 | D122: 0 | E122: 0 | F122: 0 | G122: 0 | H122: 0 | I122: 0 | J122: 0 | K122: 0 | L122: 0 | O122: 0
A123: مايو 2026 | B123: الدائرة الثانية أسرة كلي | C123: 0 | D123: 0 | E123: 0 | F123: 0 | G123: 0 | H123: 0 | I123: 0 | J123: 0 | K123: 0 | L123: 0 | O123: 0
A124: مايو 2026 | B124: الدائرة الثالثةاستئناف | C124: 0 | D124: 0 | E124: 0 | F124: 0 | G124: 0 | H124: 0 | I124: 0 | J124: 0 | K124: 0 | L124: 0 | O124: 0
A125: مايو 2026 | B125: الدائرة الرابعة اسرة كلي | C125: 0 | D125: 0 | E125: 0 | F125: 0 | G125: 0 | H125: 0 | I125: 0 | J125: 0 | K125: 0 | L125: 0 | O125: 0
A126: مايو 2026 | B126: الدائرة الخامسة أسرة كلي | C126: 0 | D126: 0 | E126: 0 | F126: 0 | G126: 0 | H126: 0 | I126: 0 | J126: 0 | K126: 0 | L126: 0 | O126: 0
A127: مايو 2026 | B127: الدائرة السادسة استئناف | C127: 0 | D127: 0 | E127: 0 | F127: 0 | G127: 0 | H127: 0 | I127: 0 | J127: 0 | K127: 0 | L127: 0 | O127: 0
A128: مايو 2026 | B128: الدائرة السابعة أسرة كلي | C128: 0 | D128: 0 | E128: 0 | F128: 0 | G128: 0 | H128: 0 | I128: 0 | J128: 0 | K128: 0 | L128: 0 | O128: 0
A129: مايو 2026 | B129: الدائرة الاولى جزئي | C129: 0 | D129: 0 | E129: 0 | F129: 0 | G129: 0 | H129: 0 | I129: 0 | J129: 0 | K129: 0 | L129: 0 | O129: 0
A130: مايو 2026 | B130: الدائرة الثانيةجزئي | C130: 0 | D130: 0 | E130: 0 | F130: 0 | G130: 0 | H130: 0 | I130: 0 | J130: 0 | K130: 0 | L130: 0 | O130: 0
A131: مايو 2026 | B131: الدائرة الثالثة جزئي | C131: 0 | D131: 0 | E131: 0 | F131: 0 | G131: 0 | H131: 0 | I131: 0 | J131: 0 | K131: 0 | L131: 0 | O131: 0
A132: مايو 2026 | B132: الدائرة الرابعة جزئي | C132: 0 | D132: 0 | E132: 0 | F132: 0 | G132: 0 | H132: 0 | I132: 0 | J132: 0 | K132: 0 | L132: 0 | O132: 0
A133: مايو 2026 | B133: الدائرة الخامسة قاصرين | C133: 0 | D133: 0 | E133: 0 | F133: 0 | G133: 0 | H133: 0 | I133: 0 | J133: 0 | K133: 0 | L133: 0 | O133: 0
... A241: ديسمبر 2026 | B241: الدائرة التاسعة تركات | C241: 0 | D241: 0 | E241: 0 | F241: 0 | G241: 0 | H241: 0 | I241: 0 | J241: 0 | K241: 0 | L241: 0 | O241: 0

Sheet حسابات_ديناميكية
A1: الدائرة | B1: المتداولة | C1: المحكومة | D1: نسبة الإنجاز | E1: المرحّلة | F1: المحجوزة | G1: المتبقي | H1: الطلبات | I1: الدعاوى المسجلة | J1: الجلسات الإلكترونية | K1: المسجلة | L1: أحكام اليوم الواحد
A2: الدائرة الأولى تركات كلي | B2: =IF(#REF!="كل الشهور",SUMIFS(بيانات_الفلتر!$E:$E,بيانات_الفلتر!$B:$B,A2),SUMIFS(بيانات_الفلتر!$E:$E,بيانات_الفلتر!$A:$A,#REF!,بيانات_الفلتر!$B:$B,A2)) -> #REF! | C2: =IF(#REF!="كل الشهور",SUMIFS(بيانات_الفلتر!$F:$F,بيانات_الفلتر!$B:$B,A2),SUMIFS(بيانات_الفلتر!$F:$F,بيانات_الفلتر!$A:$A,#REF!,بيانات_الفلتر!$B:$B,A2)) -> #REF! | D2: =IF(#REF!="كل الشهور",IFERROR(AVERAGEIFS(بيانات_الفلتر!$G:$G,بيانات_الفلتر!$B:$B,A2),0),IFERROR(AVERAGEIFS(بيانات_الفلتر!$G:$G,بيانات_الفلتر!$A:$A,#REF!,بيانات_الفلتر!$B:$B,A2),0)) -> #REF! | E2: =IF(#REF!="كل الشهور",SUMIFS(بيانات_الفلتر!$H:$H,بيانات_الفلتر!$B:$B,A2),SUMIFS(بيانات_الفلتر!$H:$H,بيانات_الفلتر!$A:$A,#REF!,بيانات_الفلتر!$B:$B,A2)) -> #REF! | F2: =IF(#REF!="كل الشهور",SUMIFS(بيانات_الفلتر!$I:$I,بيانات_الفلتر!$B:$B,A2),SUMIFS(بيانات_الفلتر!$I:$I,بيانات_الفلتر!$A:$A,#REF!,بيانات_الفلتر!$B:$B,A2)) -> #REF! | G2: =IF(#REF!="كل الشهور",SUMIFS(بيانات_الفلتر!$J:$J,بيانات_الفلتر!$B:$B,A2),SUMIFS(بيانات_الفلتر!$J:$J,بيانات_الفلتر!$A:$A,#REF!,بيانات_الفلتر!$B:$B,A2)) -> #REF! | H2: =IF(#REF!="كل الشهور",SUMIFS(بيانات_الفلتر!$C:$C,بيانات_الفلتر!$B:$B,A2),SUMIFS(بيانات_الفلتر!$C:$C,بيانات_الفلتر!$A:$A,#REF!,بيانات_الفلتر!$B:$B,A2)) -> #REF! | I2: =IF(#REF!="كل الشهور",SUMIFS(بيانات_الفلتر!$D:$D,بيانات_الفلتر!$B:$B,A2),SUMIFS(بيانات_الفلتر!$D:$D,بيانات_الفلتر!$A:$A,#REF!,بيانات_الفلتر!$B:$B,A2)) -> #REF! | J2: =IF(#REF!="كل الشهور",SUMIFS(بيانات_الفلتر!$M:$M,بيانات_الفلتر!$B:$B,A2),SUMIFS(بيانات_الفلتر!$M:$M,بيانات_الفلتر!$A:$A,#REF!,بيانات_الفلتر!$B:$B,A2)) -> #REF! | K2: =IF(#REF!="كل الشهور",SUMIFS(بيانات_الفلتر!$L:$L,بيانات_الفلتر!$B:$B,A2),SUMIFS(بيانات_الفلتر!$L:$L,بيانات_الفلتر!$A:$A,#REF!,بيانات_الفلتر!$B:$B,A2)) -> #REF! | L2: =IF(#REF!="كل الشهور",SUMIFS(بيانات_الفلتر!$O:$O,بيانات_الفلتر!$B:$B,A2),SUMIFS(بيانات_الفلتر!$O:$O,بيانات_الفلتر!$A:$A,#REF!,بيانات_الفلتر!$B:$B,A2)) -> #REF!
A3: الدائرة الثانية أسرة كلي | B3: =IF(#REF!="كل الشهور",SUMIFS(بيانات_الفلتر!$E:$E,بيانات_الفلتر!$B:$B,A3),SUMIFS(بيانات_الفلتر!$E:$E,بيانات_الفلتر!$A:$A,#REF!,بيانات_الفلتر!$B:$B,A3)) -> #REF! | C3: =IF(#REF!="كل الشهور",SUMIFS(بيانات_الفلتر!$F:$F,بيانات_الفلتر!$B:$B,A3),SUMIFS(بيانات_الفلتر!$F:$F,بيانات_الفلتر!$A:$A,#REF!,بيانات_الفلتر!$B:$B,A3)) -> #REF! | D3: =IF(#REF!="كل الشهور",IFERROR(AVERAGEIFS(بيانات_الفلتر!$G:$G,بيانات_الفلتر!$B:$B,A3),0),IFERROR(AVERAGEIFS(بيانات_الفلتر!$G:$G,بيانات_الفلتر!$A:$A,#REF!,بيانات_الفلتر!$B:$B,A3),0)) -> #REF! | E3: =IF(#REF!="كل الشهور",SUMIFS(بيانات_الفلتر!$H:$H,بيانات_الفلتر!$B:$B,A3),SUMIFS(بيانات_الفلتر!$H:$H,بيانات_الفلتر!$A:$A,#REF!,بيانات_الفلتر!$B:$B,A3)) -> #REF! | F3: =IF(#REF!="كل الشهور",SUMIFS(بيانات_الفلتر!$I:$I,بيانات_الفلتر!$B:$B,A3),SUMIFS(بيانات_الفلتر!$I:$I,بيانات_الفلتر!$A:$A,#REF!,بيانات_الفلتر!$B:$B,A3)) -> #REF! | G3: =IF(#REF!="كل الشهور",SUMIFS(بيانات_الفلتر!$J:$J,بيانات_الفلتر!$B:$B,A3),SUMIFS(بيانات_الفلتر!$J:$J,بيانات_الفلتر!$A:$A,#REF!,بيانات_الفلتر!$B:$B,A3)) -> #REF! | H3: =IF(#REF!="كل الشهور",SUMIFS(بيانات_الفلتر!$C:$C,بيانات_الفلتر!$B:$B,A3),SUMIFS(بيانات_الفلتر!$C:$C,بيانات_الفلتر!$A:$A,#REF!,بيانات_الفلتر!$B:$B,A3)) -> #REF! | I3: =IF(#REF!="كل الشهور",SUMIFS(بيانات_الفلتر!$D:$D,بيانات_الفلتر!$B:$B,A3),SUMIFS(بيانات_الفلتر!$D:$D,بيانات_الفلتر!$A:$A,#REF!,بيانات_الفلتر!$B:$B,A3)) -> #REF! | J3: =IF(#REF!="كل الشهور",SUMIFS(بيانات_الفلتر!$M:$M,بيانات_الفلتر!$B:$B,A3),SUMIFS(بيانات_الفلتر!$M:$M,بيانات_الفلتر!$A:$A,#REF!,بيانات_الفلتر!$B:$B,A3)) -> #REF! | K3: =IF(#REF!="كل الشهور",SUMIFS(بيانات_الفلتر!$L:$L,بيانات_الفلتر!$B:$B,A3),SUMIFS(بيانات_الفلتر!$L:$L,بيانات_الفلتر!$A:$A,#REF!,بيانات_الفلتر!$B:$B,A3)) -> #REF! | L3: =IF(#REF!="كل الشهور",SUMIFS(بيانات_الفلتر!$O:$O,بيانات_الفلتر!$B:$B,A3),SUMIFS(بيانات_الفلتر!$O:$O,بيانات_الفلتر!$A:$A,#REF!,بيانات_الفلتر!$B:$B,A3)) -> #REF!
A4: الدائرة الثالثةاستئناف | B4: =IF(#REF!="كل الشهور",SUMIFS(بيانات_الفلتر!$E:$E,بيانات_الفلتر!$B:$B,A4),SUMIFS(بيانات_الفلتر!$E:$E,بيانات_الفلتر!$A:$A,#REF!,بيانات_الفلتر!$B:$B,A4)) -> #REF! | C4: =IF(#REF!="كل الشهور",SUMIFS(بيانات_الفلتر!$F:$F,بيانات_الفلتر!$B:$B,A4),SUMIFS(بيانات_الفلتر!$F:$F,بيانات_الفلتر!$A:$A,#REF!,بيانات_الفلتر!$B:$B,A4)) -> #REF! | D4: =IF(#REF!="كل الشهور",IFERROR(AVERAGEIFS(بيانات_الفلتر!$G:$G,بيانات_الفلتر!$B:$B,A4),0),IFERROR(AVERAGEIFS(بيانات_الفلتر!$G:$G,بيانات_الفلتر!$A:$A,#REF!,بيانات_الفلتر!$B:$B,A4),0)) -> #REF! | E4: =IF(#REF!="كل الشهور",SUMIFS(بيانات_الفلتر!$H:$H,بيانات_الفلتر!$B:$B,A4),SUMIFS(بيانات_الفلتر!$H:$H,بيانات_الفلتر!$A:$A,#REF!,بيانات_الفلتر!$B:$B,A4)) -> #REF! | F4: =IF(#REF!="كل الشهور",SUMIFS(بيانات_الفلتر!$I:$I,بيانات_الفلتر!$B:$B,A4),SUMIFS(بيانات_الفلتر!$I:$I,بيانات_الفلتر!$A:$A,#REF!,بيانات_الفلتر!$B:$B,A4)) -> #REF! | G4: =IF(#REF!="كل الشهور",SUMIFS(بيانات_الفلتر!$J:$J,بيانات_الفلتر!$B:$B,A4),SUMIFS(بيانات_الفلتر!$J:$J,بيانات_الفلتر!$A:$A,#REF!,بيانات_الفلتر!$B:$B,A4)) -> #REF! | H4: =IF(#REF!="كل الشهور",SUMIFS(بيانات_الفلتر!$C:$C,بيانات_الفلتر!$B:$B,A4),SUMIFS(بيانات_الفلتر!$C:$C,بيانات_الفلتر!$A:$A,#REF!,بيانات_الفلتر!$B:$B,A4)) -> #REF! | I4: =IF(#REF!="كل الشهور",SUMIFS(بيانات_الفلتر!$D:$D,بيانات_الفلتر!$B:$B,A4),SUMIFS(بيانات_الفلتر!$D:$D,بيانات_الفلتر!$A:$A,#REF!,بيانات_الفلتر!$B:$B,A4)) -> #REF! | J4: =IF(#REF!="كل الشهور",SUMIFS(بيانات_الفلتر!$M:$M,بيانات_الفلتر!$B:$B,A4),SUMIFS(بيانات_الفلتر!$M:$M,بيانات_الفلتر!$A:$A,#REF!,بيانات_الفلتر!$B:$B,A4)) -> #REF! | K4: =IF(#REF!="كل الشهور",SUMIFS(بيانات_الفلتر!$L:$L,بيانات_الفلتر!$B:$B,A4),SUMIFS(بيانات_الفلتر!$L:$L,بيانات_الفلتر!$A:$A,#REF!,بيانات_الفلتر!$B:$B,A4)) -> #REF! | L4: =IF(#REF!="كل الشهور",SUMIFS(بيانات_الفلتر!$O:$O,بيانات_الفلتر!$B:$B,A4),SUMIFS(بيانات_الفلتر!$O:$O,بيانات_الفلتر!$A:$A,#REF!,بيانات_الفلتر!$B:$B,A4)) -> #REF!
A5: الدائرة الرابعة اسرة كلي | B5: =IF(#REF!="كل الشهور",SUMIFS(بيانات_الفلتر!$E:$E,بيانات_الفلتر!$B:$B,A5),SUMIFS(بيانات_الفلتر!$E:$E,بيانات_الفلتر!$A:$A,#REF!,بيانات_الفلتر!$B:$B,A5)) -> #REF! | C5: =IF(#REF!="كل الشهور",SUMIFS(بيانات_الفلتر!$F:$F,بيانات_الفلتر!$B:$B,A5),SUMIFS(بيانات_الفلتر!$F:$F,بيانات_الفلتر!$A:$A,#REF!,بيانات_الفلتر!$B:$B,A5)) -> #REF! | D5: =IF(#REF!="كل الشهور",IFERROR(AVERAGEIFS(بيانات_الفلتر!$G:$G,بيانات_الفلتر!$B:$B,A5),0),IFERROR(AVERAGEIFS(بيانات_الفلتر!$G:$G,بيانات_الفلتر!$A:$A,#REF!,بيانات_الفلتر!$B:$B,A5),0)) -> #REF! | E5: =IF(#REF!="كل الشهور",SUMIFS(بيانات_الفلتر!$H:$H,بيانات_الفلتر!$B:$B,A5),SUMIFS(بيانات_الفلتر!$H:$H,بيانات_الفلتر!$A:$A,#REF!,بيانات_الفلتر!$B:$B,A5)) -> #REF! | F5: =IF(#REF!="كل الشهور",SUMIFS(بيانات_الفلتر!$I:$I,بيانات_الفلتر!$B:$B,A5),SUMIFS(بيانات_الفلتر!$I:$I,بيانات_الفلتر!$A:$A,#REF!,بيانات_الفلتر!$B:$B,A5)) -> #REF! | G5: =IF(#REF!="كل الشهور",SUMIFS(بيانات_الفلتر!$J:$J,بيانات_الفلتر!$B:$B,A5),SUMIFS(بيانات_الفلتر!$J:$J,بيانات_الفلتر!$A:$A,#REF!,بيانات_الفلتر!$B:$B,A5)) -> #REF! | H5: =IF(#REF!="كل الشهور",SUMIFS(بيانات_الفلتر!$C:$C,بيانات_الفلتر!$B:$B,A5),SUMIFS(بيانات_الفلتر!$C:$C,بيانات_الفلتر!$A:$A,#REF!,بيانات_الفلتر!$B:$B,A5)) -> #REF! | I5: =IF(#REF!="كل الشهور",SUMIFS(بيانات_الفلتر!$D:$D,بيانات_الفلتر!$B:$B,A5),SUMIFS(بيانات_الفلتر!$D:$D,بيانات_الفلتر!$A:$A,#REF!,بيانات_الفلتر!$B:$B,A5)) -> #REF! | J5: =IF(#REF!="كل الشهور",SUMIFS(بيانات_الفلتر!$M:$M,بيانات_الفلتر!$B:$B,A5),SUMIFS(بيانات_الفلتر!$M:$M,بيانات_الفلتر!$A:$A,#REF!,بيانات_الفلتر!$B:$B,A5)) -> #REF! | K5: =IF(#REF!="كل الشهور",SUMIFS(بيانات_الفلتر!$L:$L,بيانات_الفلتر!$B:$B,A5),SUMIFS(بيانات_الفلتر!$L:$L,بيانات_الفلتر!$A:$A,#REF!,بيانات_الفلتر!$B:$B,A5)) -> #REF! | L5: =IF(#REF!="كل الشهور",SUMIFS(بيانات_الفلتر!$O:$O,بيانات_الفلتر!$B:$B,A5),SUMIFS(بيانات_الفلتر!$O:$O,بيانات_الفلتر!$A:$A,#REF!,بيانات_الفلتر!$B:$B,A5)) -> #REF!
A6: الدائرة الخامسة أسرة كلي | B6: =IF(#REF!="كل الشهور",SUMIFS(بيانات_الفلتر!$E:$E,بيانات_الفلتر!$B:$B,A6),SUMIFS(بيانات_الفلتر!$E:$E,بيانات_الفلتر!$A:$A,#REF!,بيانات_الفلتر!$B:$B,A6)) -> #REF! | C6: =IF(#REF!="كل الشهور",SUMIFS(بيانات_الفلتر!$F:$F,بيانات_الفلتر!$B:$B,A6),SUMIFS(بيانات_الفلتر!$F:$F,بيانات_الفلتر!$A:$A,#REF!,بيانات_الفلتر!$B:$B,A6)) -> #REF! | D6: =IF(#REF!="كل الشهور",IFERROR(AVERAGEIFS(بيانات_الفلتر!$G:$G,بيانات_الفلتر!$B:$B,A6),0),IFERROR(AVERAGEIFS(بيانات_الفلتر!$G:$G,بيانات_الفلتر!$A:$A,#REF!,بيانات_الفلتر!$B:$B,A6),0)) -> #REF! | E6: =IF(#REF!="كل الشهور",SUMIFS(بيانات_الفلتر!$H:$H,بيانات_الفلتر!$B:$B,A6),SUMIFS(بيانات_الفلتر!$H:$H,بيانات_الفلتر!$A:$A,#REF!,بيانات_الفلتر!$B:$B,A6)) -> #REF! | F6: =IF(#REF!="كل الشهور",SUMIFS(بيانات_الفلتر!$I:$I,بيانات_الفلتر!$B:$B,A6),SUMIFS(بيانات_الفلتر!$I:$I,بيانات_الفلتر!$A:$A,#REF!,بيانات_الفلتر!$B:$B,A6)) -> #REF! | G6: =IF(#REF!="كل الشهور",SUMIFS(بيانات_الفلتر!$J:$J,بيانات_الفلتر!$B:$B,A6),SUMIFS(بيانات_الفلتر!$J:$J,بيانات_الفلتر!$A:$A,#REF!,بيانات_الفلتر!$B:$B,A6)) -> #REF! | H6: =IF(#REF!="كل الشهور",SUMIFS(بيانات_الفلتر!$C:$C,بيانات_الفلتر!$B:$B,A6),SUMIFS(بيانات_الفلتر!$C:$C,بيانات_الفلتر!$A:$A,#REF!,بيانات_الفلتر!$B:$B,A6)) -> #REF! | I6: =IF(#REF!="كل الشهور",SUMIFS(بيانات_الفلتر!$D:$D,بيانات_الفلتر!$B:$B,A6),SUMIFS(بيانات_الفلتر!$D:$D,بيانات_الفلتر!$A:$A,#REF!,بيانات_الفلتر!$B:$B,A6)) -> #REF! | J6: =IF(#REF!="كل الشهور",SUMIFS(بيانات_الفلتر!$M:$M,بيانات_الفلتر!$B:$B,A6),SUMIFS(بيانات_الفلتر!$M:$M,بيانات_الفلتر!$A:$A,#REF!,بيانات_الفلتر!$B:$B,A6)) -> #REF! | K6: =IF(#REF!="كل الشهور",SUMIFS(بيانات_الفلتر!$L:$L,بيانات_الفلتر!$B:$B,A6),SUMIFS(بيانات_الفلتر!$L:$L,بيانات_الفلتر!$A:$A,#REF!,بيانات_الفلتر!$B:$B,A6)) -> #REF! | L6: =IF(#REF!="كل الشهور",SUMIFS(بيانات_الفلتر!$O:$O,بيانات_الفلتر!$B:$B,A6),SUMIFS(بيانات_الفلتر!$O:$O,بيانات_الفلتر!$A:$A,#REF!,بيانات_الفلتر!$B:$B,A6)) -> #REF!
A7: الدائرة السادسة استئناف | B7: =IF(#REF!="كل الشهور",SUMIFS(بيانات_الفلتر!$E:$E,بيانات_الفلتر!$B:$B,A7),SUMIFS(بيانات_الفلتر!$E:$E,بيانات_الفلتر!$A:$A,#REF!,بيانات_الفلتر!$B:$B,A7)) -> #REF! | C7: =IF(#REF!="كل الشهور",SUMIFS(بيانات_الفلتر!$F:$F,بيانات_الفلتر!$B:$B,A7),SUMIFS(بيانات_الفلتر!$F:$F,بيانات_الفلتر!$A:$A,#REF!,بيانات_الفلتر!$B:$B,A7)) -> #REF! | D7: =IF(#REF!="كل الشهور",IFERROR(AVERAGEIFS(بيانات_الفلتر!$G:$G,بيانات_الفلتر!$B:$B,A7),0),IFERROR(AVERAGEIFS(بيانات_الفلتر!$G:$G,بيانات_الفلتر!$A:$A,#REF!,بيانات_الفلتر!$B:$B,A7),0)) -> #REF! | E7: =IF(#REF!="كل الشهور",SUMIFS(بيانات_الفلتر!$H:$H,بيانات_الفلتر!$B:$B,A7),SUMIFS(بيانات_الفلتر!$H:$H,بيانات_الفلتر!$A:$A,#REF!,بيانات_الفلتر!$B:$B,A7)) -> #REF! | F7: =IF(#REF!="كل الشهور",SUMIFS(بيانات_الفلتر!$I:$I,بيانات_الفلتر!$B:$B,A7),SUMIFS(بيانات_الفلتر!$I:$I,بيانات_الفلتر!$A:$A,#REF!,بيانات_الفلتر!$B:$B,A7)) -> #REF! | G7: =IF(#REF!="كل الشهور",SUMIFS(بيانات_الفلتر!$J:$J,بيانات_الفلتر!$B:$B,A7),SUMIFS(بيانات_الفلتر!$J:$J,بيانات_الفلتر!$A:$A,#REF!,بيانات_الفلتر!$B:$B,A7)) -> #REF! | H7: =IF(#REF!="كل الشهور",SUMIFS(بيانات_الفلتر!$C:$C,بيانات_الفلتر!$B:$B,A7),SUMIFS(بيانات_الفلتر!$C:$C,بيانات_الفلتر!$A:$A,#REF!,بيانات_الفلتر!$B:$B,A7)) -> #REF! | I7: =IF(#REF!="كل الشهور",SUMIFS(بيانات_الفلتر!$D:$D,بيانات_الفلتر!$B:$B,A7),SUMIFS(بيانات_الفلتر!$D:$D,بيانات_الفلتر!$A:$A,#REF!,بيانات_الفلتر!$B:$B,A7)) -> #REF! | J7: =IF(#REF!="كل الشهور",SUMIFS(بيانات_الفلتر!$M:$M,بيانات_الفلتر!$B:$B,A7),SUMIFS(بيانات_الفلتر!$M:$M,بيانات_الفلتر!$A:$A,#REF!,بيانات_الفلتر!$B:$B,A7)) -> #REF! | K7: =IF(#REF!="كل الشهور",SUMIFS(بيانات_الفلتر!$L:$L,بيانات_الفلتر!$B:$B,A7),SUMIFS(بيانات_الفلتر!$L:$L,بيانات_الفلتر!$A:$A,#REF!,بيانات_الفلتر!$B:$B,A7)) -> #REF! | L7: =IF(#REF!="كل الشهور",SUMIFS(بيانات_الفلتر!$O:$O,بيانات_الفلتر!$B:$B,A7),SUMIFS(بيانات_الفلتر!$O:$O,بيانات_الفلتر!$A:$A,#REF!,بيانات_الفلتر!$B:$B,A7)) -> #REF!
